Workbook
Name Accomodation: 'Dropdown Lists'!$AG$13:$AG$15
Name Allowances: 'Dropdown Lists'!$P$32:$P$34
Name Bank_Fees: 'Dropdown Lists'!$F$13:$F$15
Name Bonuses: 'Dropdown Lists'!$C$32:$C$34
Name Books_Materials: 'Dropdown Lists'!$B$13:$B$17
Name Business_Income: 'Dropdown Lists'!$A$22:$A$24
Name Car_Insurance_Registration: 'Dropdown Lists'!$AD$13:$AD$15
Name Clothing_Accessories: 'Dropdown Lists'!$U$13:$U$17
Name Commissions_Incentives: 'Dropdown Lists'!$B$22:$B$23
Name Content_Creation: 'Dropdown Lists'!$K$32:$K$36
Name Data_Analysis: 'Dropdown Lists'!$E$32:$E$33
Name Debt_Repayment: 'Dropdown Lists'!$D$13:$D$14
Name Design: 'Dropdown Lists'!$F$32
Name Digital_Sales: 'Dropdown Lists'!$L$32:$L$34
Name Education: 'Dropdown Lists'!$A$3:$A$5
Name Emergency_Expenses: 'Dropdown Lists'!$S$13:$S$15
Name Employee_Staff_Costs: 'Dropdown Lists'!$AM$13:$AM$16
Name Entertainment_Recreation: 'Dropdown Lists'!$W$13:$W$16
Name Financial: 'Dropdown Lists'!$I$32:$I$34
Name Financial_Obligations: 'Dropdown Lists'!$B$3:$B$7
Name Freelance_Contract: 'Dropdown Lists'!$C$22:$C$25
Name Fuel_Gas: 'Dropdown Lists'!$AA$13:$AA$15
Name Furniture_Appliances: 'Dropdown Lists'!$R$13:$R$16
Name Gift_Donations: 'Dropdown Lists'!$Z$13:$Z$15
Name Gift_Donations_Income: 'Dropdown Lists'!$M$32:$M$33
Name Groceries: 'Dropdown Lists'!$P$13:$P$16
Name Gym_Fitness: 'Dropdown Lists'!$X$13:$X$16
Name Haircare_Beauty: 'Dropdown Lists'!$V$13:$V$16
Name Health_Insurance: 'Dropdown Lists'!$K$13
Name Healthy_Wellness: 'Dropdown Lists'!$C$3:$C$6
Name Home_Maintenance: 'Dropdown Lists'!$Q$13:$Q$16
Name Insurance_Premiums: 'Dropdown Lists'!$H$13:$H$15
Name Internet_Cable: 'Dropdown Lists'!$O$13:$O$15
Name Investments: 'Dropdown Lists'!$D$22:$D$23
Name Living_Household: 'Dropdown Lists'!$D$3:$D$8
Name Marketing_Advertising: 'Dropdown Lists'!$AK$13:$AK$15
Name Meals_Drinks: 'Dropdown Lists'!$AH$13:$AH$15
Name Medical_Bills: 'Dropdown Lists'!$I$13:$I$16
Name Medications: 'Dropdown Lists'!$J$13:$J$14
Name Miscellaneous: 'Dropdown Lists'!$N$32
Name Miscellaneous_Others: 'Dropdown Lists'!$E$3:$E$4
Name Monthly_Pay: 'Dropdown Lists'!$Q$32:$Q$33
Name Office_Supplies: 'Dropdown Lists'!$AJ$13:$AJ$16
Name Online_Courses: 'Dropdown Lists'!$C$13:$C$15
Name Online_Digital_Income: 'Dropdown Lists'!$E$22:$E$23
Name Other_Income: 'Dropdown Lists'!$F$22:$F$24
Name Parking_Tolls: 'Dropdown Lists'!$AE$13:$AE$15
Name Personal_Lifestyle: 'Dropdown Lists'!$F$3:$F$8
Name Product_Sales: 'Dropdown Lists'!$A$32:$A$35
Name Professional_Fees: 'Dropdown Lists'!$AO$13:$AO$15
Name Property: 'Dropdown Lists'!$J$32:$J$33
Name Public_Transport: 'Dropdown Lists'!$AC$13:$AC$15
Name Refunds_Rebates: 'Dropdown Lists'!$O$32:$O$33
Name Rent: 'Dropdown Lists'!$M$13:$M$16
Name Salary_Wages: 'Dropdown Lists'!$G$22:$G$23
Name Sales: 'Dropdown Lists'!$D$32:$D$33
Name SAVINGS_GOAL_NAMES: 'Dropdown Lists'!$A$49:$A$55
Name Savings_Investment: 'Dropdown Lists'!$E$13:$E$16
Name Services: 'Dropdown Lists'!$B$32:$B$34
Name Slicer_Frequency: #N/A

Sheet Dashboard
B1: ANNUAL INCOME VS EXPENSE SUMMARY
B2: Income Summary | C2: =SUM('Annual Summary'!C9:C20) -> 14500
B3: Expense Summary | C3: =SUM('Annual Summary'!D9:D20) -> 22800
B4: Net Balance | C4: =C2-C3 -> -8300

Sheet Annual Summary
B1: CURRENT MONTH | C1: =(TEXT(TODAY(), "mmmm, yyyy")) -> January, 2026
B2: ACTUAL INCOMES | C2: =IF($B$9="", 0, IFERROR(INDEX(Table3[Actual Income], MATCH(TEXT(TODAY(), "mmmm"), Table3[Month], 0)),0)) -> 0
B3: ACTUAL EXPENSES | C3: =IF($B$9="", 0, IFERROR(INDEX(Table3[Actual Expenses], MATCH(TEXT(TODAY(), "mmmm"), Table3[Month], 0)), 0)) -> 0
B4: NET BALANCE | C4: =(C2-C3) -> 0
B7: ANNUAL SUMMARY
B8: Month | C8: Actual Income | D8: Actual Expenses | E8: NET BALANCE
B9: {=IFERROR(INDEX(Expense[Month], MATCH(0, IF(Expense[Month]<>"", COUNTIF($B$8:B8, Expense[Month]), 1), 0)), IFERROR(INDEX(Table1[Month], MATCH(0, IF(Table1[Month]<>"", COUNTIF($B$8:B8,Table1[Month]), 1), 0)),""))} -> November | C9: =SUMIF('Income Tracker'!C:C, 'Annual Summary'!B9, 'Income Tracker'!H:H) -> 14500 | D9: =SUMIF('Expenses Tracker'!C:C, 'Annual Summary'!B9, 'Expenses Tracker'!H:H) -> 22800 | E9: =(Table3[[#This Row],[Actual Income]]-Table3[[#This Row],[Actual Expenses]]) -> -8300
B10: {=IFERROR(INDEX(Expense[Month], MATCH(0, IF(Expense[Month]<>"", COUNTIF($B$8:B9, Expense[Month]), 1), 0)), IFERROR(INDEX(Table1[Month], MATCH(0, IF(Table1[Month]<>"", COUNTIF($B$8:B9,Table1[Month]), 1), 0)),""))} | C10: =SUMIF('Income Tracker'!C:C, 'Annual Summary'!B10, 'Income Tracker'!H:H) -> 0 | D10: =SUMIF('Expenses Tracker'!C:C, 'Annual Summary'!B10, 'Expenses Tracker'!H:H) -> 0 | E10: =(Table3[[#This Row],[Actual Income]]-Table3[[#This Row],[Actual Expenses]]) -> 0
B11: {=IFERROR(INDEX(Expense[Month], MATCH(0, IF(Expense[Month]<>"", COUNTIF($B$8:B10, Expense[Month]), 1), 0)), IFERROR(INDEX(Table1[Month], MATCH(0, IF(Table1[Month]<>"", COUNTIF($B$8:B10,Table1[Month]), 1), 0)),""))} | C11: =SUMIF('Income Tracker'!C:C, 'Annual Summary'!B11, 'Income Tracker'!H:H) -> 0 | D11: =SUMIF('Expenses Tracker'!C:C, 'Annual Summary'!B11, 'Expenses Tracker'!H:H) -> 0 | E11: =(Table3[[#This Row],[Actual Income]]-Table3[[#This Row],[Actual Expenses]]) -> 0
B12: {=IFERROR(INDEX(Expense[Month], MATCH(0, IF(Expense[Month]<>"", COUNTIF($B$8:B11, Expense[Month]), 1), 0)), IFERROR(INDEX(Table1[Month], MATCH(0, IF(Table1[Month]<>"", COUNTIF($B$8:B11,Table1[Month]), 1), 0)),""))} | C12: =SUMIF('Income Tracker'!C:C, 'Annual Summary'!B12, 'Income Tracker'!H:H) -> 0 | D12: =SUMIF('Expenses Tracker'!C:C, 'Annual Summary'!B12, 'Expenses Tracker'!H:H) -> 0 | E12: =(Table3[[#This Row],[Actual Income]]-Table3[[#This Row],[Actual Expenses]]) -> 0
B13: {=IFERROR(INDEX(Expense[Month], MATCH(0, IF(Expense[Month]<>"", COUNTIF($B$8:B12, Expense[Month]), 1), 0)), IFERROR(INDEX(Table1[Month], MATCH(0, IF(Table1[Month]<>"", COUNTIF($B$8:B12,Table1[Month]), 1), 0)),""))} | C13: =SUMIF('Income Tracker'!C:C, 'Annual Summary'!B13, 'Income Tracker'!H:H) -> 0 | D13: =SUMIF('Expenses Tracker'!C:C, 'Annual Summary'!B13, 'Expenses Tracker'!H:H) -> 0 | E13: =(Table3[[#This Row],[Actual Income]]-Table3[[#This Row],[Actual Expenses]]) -> 0
B14: {=IFERROR(INDEX(Expense[Month], MATCH(0, IF(Expense[Month]<>"", COUNTIF($B$8:B13, Expense[Month]), 1), 0)), IFERROR(INDEX(Table1[Month], MATCH(0, IF(Table1[Month]<>"", COUNTIF($B$8:B13,Table1[Month]), 1), 0)),""))} | C14: =SUMIF('Income Tracker'!C:C, 'Annual Summary'!B14, 'Income Tracker'!H:H) -> 0 | D14: =SUMIF('Expenses Tracker'!C:C, 'Annual Summary'!B14, 'Expenses Tracker'!H:H) -> 0 | E14: =(Table3[[#This Row],[Actual Income]]-Table3[[#This Row],[Actual Expenses]]) -> 0
B15: {=IFERROR(INDEX(Expense[Month], MATCH(0, IF(Expense[Month]<>"", COUNTIF($B$8:B14, Expense[Month]), 1), 0)), IFERROR(INDEX(Table1[Month], MATCH(0, IF(Table1[Month]<>"", COUNTIF($B$8:B14,Table1[Month]), 1), 0)),""))} | C15: =SUMIF('Income Tracker'!C:C, 'Annual Summary'!B15, 'Income Tracker'!H:H) -> 0 | D15: =SUMIF('Expenses Tracker'!C:C, 'Annual Summary'!B15, 'Expenses Tracker'!H:H) -> 0 | E15: =(Table3[[#This Row],[Actual Income]]-Table3[[#This Row],[Actual Expenses]]) -> 0
B16: {=IFERROR(INDEX(Expense[Month], MATCH(0, IF(Expense[Month]<>"", COUNTIF($B$8:B15, Expense[Month]), 1), 0)), IFERROR(INDEX(Table1[Month], MATCH(0, IF(Table1[Month]<>"", COUNTIF($B$8:B15,Table1[Month]), 1), 0)),""))} | C16: =SUMIF('Income Tracker'!C:C, 'Annual Summary'!B16, 'Income Tracker'!H:H) -> 0 | D16: =SUMIF('Expenses Tracker'!C:C, 'Annual Summary'!B16, 'Expenses Tracker'!H:H) -> 0 | E16: =(Table3[[#This Row],[Actual Income]]-Table3[[#This Row],[Actual Expenses]]) -> 0
B17: {=IFERROR(INDEX(Expense[Month], MATCH(0, IF(Expense[Month]<>"", COUNTIF($B$8:B16, Expense[Month]), 1), 0)), IFERROR(INDEX(Table1[Month], MATCH(0, IF(Table1[Month]<>"", COUNTIF($B$8:B16,Table1[Month]), 1), 0)),""))} | C17: =SUMIF('Income Tracker'!C:C, 'Annual Summary'!B17, 'Income Tracker'!H:H) -> 0 | D17: =SUMIF('Expenses Tracker'!C:C, 'Annual Summary'!B17, 'Expenses Tracker'!H:H) -> 0 | E17: =(Table3[[#This Row],[Actual Income]]-Table3[[#This Row],[Actual Expenses]]) -> 0
B18: {=IFERROR(INDEX(Expense[Month], MATCH(0, IF(Expense[Month]<>"", COUNTIF($B$8:B17, Expense[Month]), 1), 0)), IFERROR(INDEX(Table1[Month], MATCH(0, IF(Table1[Month]<>"", COUNTIF($B$8:B17,Table1[Month]), 1), 0)),""))} | C18: =SUMIF('Income Tracker'!C:C, 'Annual Summary'!B18, 'Income Tracker'!H:H) -> 0 | D18: =SUMIF('Expenses Tracker'!C:C, 'Annual Summary'!B18, 'Expenses Tracker'!H:H) -> 0 | E18: =(Table3[[#This Row],[Actual Income]]-Table3[[#This Row],[Actual Expenses]]) -> 0
B19: {=IFERROR(INDEX(Expense[Month], MATCH(0, IF(Expense[Month]<>"", COUNTIF($B$8:B18, Expense[Month]), 1), 0)), IFERROR(INDEX(Table1[Month], MATCH(0, IF(Table1[Month]<>"", COUNTIF($B$8:B18,Table1[Month]), 1), 0)),""))} | C19: =SUMIF('Income Tracker'!C:C, 'Annual Summary'!B19, 'Income Tracker'!H:H) -> 0 | D19: =SUMIF('Expenses Tracker'!C:C, 'Annual Summary'!B19, 'Expenses Tracker'!H:H) -> 0 | E19: =(Table3[[#This Row],[Actual Income]]-Table3[[#This Row],[Actual Expenses]]) -> 0
B20: {=IFERROR(INDEX(Expense[Month], MATCH(0, IF(Expense[Month]<>"", COUNTIF($B$8:B19, Expense[Month]), 1), 0)), IFERROR(INDEX(Table1[Month], MATCH(0, IF(Table1[Month]<>"", COUNTIF($B$8:B19,Table1[Month]), 1), 0)),""))} | C20: =SUMIF('Income Tracker'!C:C, 'Annual Summary'!B20, 'Income Tracker'!H:H) -> 0 | D20: =SUMIF('Expenses Tracker'!C:C, 'Annual Summary'!B20, 'Expenses Tracker'!H:H) -> 0 | E20: =(Table3[[#This Row],[Actual Income]]-Table3[[#This Row],[Actual Expenses]]) -> 0

Sheet Expenses Tracker
B1: Date | C1: Month | D1: Category | E1: Type | F1: Description | G1: Budgeted | H1: Actual | I1: Difference
B2: 45962 | C2: =IF(Expense[[#This Row],[Date]]="","", TEXT(Expense[[#This Row],[Date]], "mmmm")) -> November | D2: Healthy_Wellness | E2: Health_Insurance | F2: Premiunm Payment | G2: 10000 | H2: 15000 | I2: =G2-H2 -> -5000
B3: 45962 | C3: =IF(Expense[[#This Row],[Date]]="","", TEXT(Expense[[#This Row],[Date]], "mmmm")) -> November | D3: Travel | E3: Tours_Leisure | F3: Entertainment | G3: 5000 | H3: 4500 | I3: =G3-H3 -> 500
B4: 45963 | C4: =IF(Expense[[#This Row],[Date]]="","", TEXT(Expense[[#This Row],[Date]], "mmmm")) -> November | D4: Miscellaneous_Others | E4: Unplanned_Purchases | F4: Other | G4: 2000 | H4: 1500 | I4: =G4-H4 -> 500
B5: 45963 | C5: =IF(Expense[[#This Row],[Date]]="","", TEXT(Expense[[#This Row],[Date]], "mmmm")) -> November | D5: Living_Household | E5: Utilities | F5: Electricity | G5: 800 | H5: 900 | I5: =G5-H5 -> -100
B6: 45963 | C6: =IF(Expense[[#This Row],[Date]]="","", TEXT(Expense[[#This Row],[Date]], "mmmm")) -> November | D6: Transportation | E6: Vehicle_Maintenance | F6: Servicing | G6: 900 | H6: 900 | I6: =G6-H6 -> 0
C7: =IF(Expense[[#This Row],[Date]]="","", TEXT(Expense[[#This Row],[Date]], "mmmm")) | I7: =G7-H7 -> 0

Sheet Income Tracker
B4: Date | C4: Month | D4: Source | E4: Type | F4: Description | G4: Estimate | H4: Actual | I4: Difference
B5: 45962 | C5: =IF(Table1[[#This Row],[Date]]="","", TEXT(Table1[[#This Row],[Date]], "mmmm")) -> November | D5: Online_Digital_Income | E5: Content_Creation | F5: Ads_Sponsorship | G5: 9000 | H5: 8500 | I5: =H5-G5 -> -500
B6: 45963 | C6: =IF(Table1[[#This Row],[Date]]="","", TEXT(Table1[[#This Row],[Date]], "mmmm")) -> November | D6: Freelance_Contract | E6: Technical_Projects | F6: IT_Support | G6: 3000 | H6: 3000 | I6: =H6-G6 -> 0
B7: 45964 | C7: =IF(Table1[[#This Row],[Date]]="","", TEXT(Table1[[#This Row],[Date]], "mmmm")) -> November | D7: Other_Income | E7: Miscellaneous | F7: One_Time_Income | G7: 2500 | H7: 3000 | I7: =H7-G7 -> 500
C12: =IF(Table1[[#This Row],[Date]]="","", TEXT(Table1[[#This Row],[Date]], "mmmm"))
C13: =IF(Table1[[#This Row],[Date]]="","", TEXT(Table1[[#This Row],[Date]], "mmmm"))
C14: =IF(Table1[[#This Row],[Date]]="","", TEXT(Table1[[#This Row],[Date]], "mmmm"))

Sheet PT Expense&Bill Distribution
B1: Month | C1: (All) | H1: Frequency | I1: (All)
B3: Row Labels | C3: Sum of Actual | H3: Row Labels | I3: Sum of Amount
B4: Healthy_Wellness | C4: 15000 | H4: (blank)
B5: Living_Household | C5: 900 | H5: Spotify | I5: 10
B6: (blank) | H6: Shop Rent | I6: 20000
B7: Travel | C7: 4500 | H7: Internet | I7: 3200
B8: Miscellaneous_Others | C8: 1500 | H8: Charge | I8: 1000
B9: Transportation | C9: 900 | H9: Grand Total | I9: 24210
B10: Grand Total | C10: 22800

Sheet Dropdown Lists
A1: EXPENSES CATEGORY/TYPE
A2: Education | B2: Financial_Obligations | C2: Healthy_Wellness | D2: Living_Household | E2: Miscellaneous_Others | F2: Personal_Lifestyle | G2: Transportation | H2: Travel | I2: Work_Business
A3: Books_Materials | B3: Bank_Fees | C3: Health_Insurance | D3: Furniture_Appliances | E3: Emergency_Expenses | F3: Clothing_Accessories | G3: Car_Insurance_Registration | H3: Accomodation | I3: Employee_Staff Costs
A4: Online_Courses | B4: Debt_Repayment | C4: Medical_Bills | D4: Groceries | E4: Unplanned_Purchases | F4: Entertainment_Recreation | G4: Fuel_Gas | H4: Meals_Drinks | I4: Marketing_Advertising
A5: Tuition_Fees | B5: Insurance_Premiums | C5: Medications | D5: Home_Maintenance | F5: Gift_Donations | G5: Parking_Tolls | H5: Tours_Leisure | I5: Office_Supplies
B6: Savings_Investment | C6: Wellness_Therapy | D6: Internet_Cable | F6: Gym_Fitness | G6: Public_Transport | H6: Transport_Flight | I6: Professional_Fees
B7: Taxes_Levies | D7: Rent_Mortgage | F7: Haircare_Beauty | G7: Vehicle_Maintenance | I7: Training_Development
D8: Utilities | F8: Subscription | I8: Transport_Logistics
A11: EXPENSE DESCRIPTION
A12: Tuition_Fees | B12: Books_Materials | C12: Online_Courses | D12: Debt_Repayment | E12: Savings_Investment | F12: Bank_Fees | G12: Taxes_Levies | H12: Insurance_Premiums | I12: Medical_Bills | J12: Medications | K12: Health_Insurance | L12: Wellness_Therapy | M12: Rent | N12: Utilities | O12: Internet_Cable | P12: Groceries | Q12: Home_Maintenance | R12: Furniture_Appliances | S12: Emergency_Expenses | T12: Unplanned_Purchases | U12: Clothing_Accessories | V12: Haircare_Beauty | W12: Entertainment_Recreation | X12: Gym_Fitness | Y12: Subscription | Z12: Gift_Donations | AA12: Fuel_Gas | AB12: Vehicle_Maintenance | AC12: Public_Transport | AD12: Car_Insurance_Registration | AE12: Parking_Tolls | AF12: Transport_Flight | AG12: Accomodation | AH12: Meals_Drinks | AI12: Tours_Leisure | AJ12: Office_Supplies | AK12: Marketing_Advertising | AL12: Transport_Logistics | AM12: Employee_Staff_Costs | AN12: Training_Development | AO12: Professional_Fees
A13: School Fees | B13: Notebooks | C13: Coursera Learning | D13: Borrowed Money | E13: Mutual Funds | F13: ATM Charges | G13: Income Taxes | H13: Business Insurance | I13: Clinic Bill | J13: Drugs | K13: Premiunm Payment | L13: Counseling | M13: Monthly House Rent | N13: Electricity | O13: Cable TV | P13: Beverages | Q13: Cleaning Services | R13: Décor | S13: Health Issues | T13: Impulse Buy | U13: Clothes | V13: Barbing | W13: Concerts | X13: Gym Membership | Y13: Apple Music | Z13: Birthday Presents | AA13: Diesel | AB13: Oil Change | AC13: Bus | AD13: Documents | AE13: Gate Fees | AF13: Airfare | AG13: Airbnb | AH13: Beverages on Trip | AI13: Entertainment | AJ13: Materials | AK13: Flyers | AL13: Courier | AM13: Bonuses | AN13: Certifications | AO13: Accounting Services
A14: Training Fees | B14: Others | C14: Linkedln Learniing | D14: Loan Repayments | E14: Others | F14: Card Fees | G14: Local Govt Levies | H14: Life Insurance | I14: Dental Bill | J14: Supplements | L14: Physiotherapy | M14: Mortgage Repayment | N14: Gas Refill | O14: Phone Data Plans | P14: Cleaning Supplies | Q14: Electrical | R14: Electronics | S14: Others | T14: Other | U14: Fashion Bags | V14: Cosmetics | W14: Events | X14: Others | Y14: Magazines | Z14: Charity | AA14: Gas Top-ups | AB14: Servicing | AC14: Ride Hailing | AD14: Insurance | AE14: Parking Tickets | AF14: Bus Tickets | AG14: Hotel | AH14: Food on Trip | AI14: Excursion | AJ14: Paper | AK14: Promotions | AL14: Delivery | AM14: Salaries | AN14: Courses | AO14: Consulting Services
B15: School Bags | C15: Udemy Learning | E15: Personal Savings | F15: Transfer Charges | H15: Property Insurance | I15: Hospital Bill | L15: Spa | M15: Service Charge | N15: Prepaid Meter | O15: WI-FI Subscription | P15: Food Items | Q15: Plumbing | R15: Furniture | S15: Unexpected Repairs | U15: Fashion Items | V15: Salon | W15: Hangouts | X15: Supplements | Y15: Netflix | Z15: Family Support | AA15: Petrol | AB15: Spare Parts | AC15: Taxi | AD15: License Renewal | AE15: Toll Gate Charges | AF15: Train Tickets | AG15: Lodging | AH15: Snacks on Trip | AI15: Sightseeing | AJ15: Printer Ink | AK15: Social Media Ads | AL15: Fuel for Business Trips | AM15: Wages | AN15: Workshops | AO15: Legal Services
B16: Textbooks | E16: Stocks | I16: Others | M16: Yearly House Rent | N16: Waste Disposal | P16: Toiletries | Q16: Repairs | R16: Replacements | U16: Jewelry | V16: Skincare | W16: Movies | X16: Workout Gear | Y16: Others | AB16: Tires | AJ16: Stationery | AM16: Welfare
B17: Uniforms | N17: Water | U17: Shoes | Y17: Spotify
A20: INCOME SOURCE/TYPE
A21: Business_Income | B21: Commissions_Incentives | C21: Freelance_Contract | D21: Investments | E21: Online_Digital_Income | F21: Other_Income | G21: Salary_Wages
A22: Product_Sales | B22: Bonuses | C22: Data_Analysis | D22: Financial | E22: Content_Creation | F22: Gift_Donations_Income | G22: Allowances
A23: Services | B23: Sales | C23: Design | D23: Property | E23: Digital_Sales | F23: Miscellaneous | G23: Monthly_Pay
A24: Discounts | C24: Technical_Projects | F24: Refunds_Rebates
C25: Writing
A30: INCOME DESCRIPTION
A31: Product_Sales | B31: Services | C31: Bonuses | D31: Sales | E31: Data_Analysis | F31: Design | G31: Technical_Projects | H31: Writing | I31: Financial | J31: Property | K31: Content_Creation | L31: Digital_Sales | M31: Gift_Donations_Income | N31: Miscellaneous | O31: Refunds_Rebates | P31: Allowances | Q31: Monthly_Pay
A32: Online_Store | B32: Consulting | C32: Performance_Bonus | D32: Product_Commission | E32: Business_Analysis | F32: Graphic_Design | G32: IT_Support | H32: Content_Writiing | I32: Dividends | J32: Real_Estate_Profit | K32: Ads_Sponsorship | L32: Ebooks | M32: Cash_Gift | N32: One_Time_Income | O32: Purchase_Refund | P32: Housing_Allowance | Q32: Base_Salary
A33: Retail_Sales | B33: Delivery_Logistics | C33: Year_End_Bonus | D33: Service_Commission | E33: Financial_Analysis | G33: Web_Development | I33: Mutual_Fund_Returns | J33: Rent_Income | K33: Facebook | L33: Online_Course | M33: Family_Support | O33: Tax_Refund | P33: Meal_Allowance | Q33: Overtime
A34: Wholesale | B34: Hair_Beauty_Services | C34: Monthly_Bonus | I34: Stock_Profit | K34: Other_Social_Media | L34: Templates | P34: Transport_Allowance
K35: Tiktok
K36: Youtube
A39: BILL_FREQUENCY | C39: BILL_NAME
A40: Monthly | C40: Charge
A41: Quarterly | C41: Internet
A42: Bi-Annual | C42: Internet
A43: Annual | C43: Netflix
C44: Prime Video
C45: Shop Rent
C46: Spotify
C47: Twitter
A48: SAVINGS_GOAL_NAMES | C48: Youtube
A49: Emergency_Fund
A50: Investment_Fund
...
